<?xml version="1.0" ?>
<robot name="trial_noovy2">
  <joint name="trial_noovy2__link_0_JOINT_0" type="revolute">
    <parent link="trial_noovy2__link_0"/>
    <child link="trial_noovy2__link_1"/>
    <origin rpy="0  0  0" xyz="0     0.115  0"/>
    <axis xyz="0.99955  0.02998  0"/>
    <limit effort="-1.0" lower="-1.79769e+308" upper="1.79769e+308" velocity="-1.0"/>
  </joint>
  <joint name="trial_noovy2__link_0_JOINT_2" type="revolute">
    <parent link="trial_noovy2__link_0"/>
    <child link="trial_noovy2__link_1_clone"/>
    <origin rpy="3.14159000e+00   1.59000000e-03   3.14159000e+00" xyz="0     0.115  0"/>
    <axis xyz="-0.99999  0       0.00159"/>
    <limit effort="-1.0" lower="-1.79769e+308" upper="1.79769e+308" velocity="-1.0"/>
  </joint>
  <joint name="trial_noovy2__link_0_JOINT_3" type="revolute">
    <parent link="trial_noovy2__link_0"/>
    <child link="trial_noovy2__link_1_clone_clone"/>
    <origin rpy="3.14  0    0" xyz="0      -0.115    0.00018"/>
    <axis xyz="1  0  0"/>
    <limit effort="-1.0" lower="-1.79769e+308" upper="1.79769e+308" velocity="-1.0"/>
  </joint>
  <joint name="trial_noovy2__link_0_JOINT_4" type="revolute">
    <parent link="trial_noovy2__link_0"/>
    <child link="trial_noovy2__link_1_clone_clone_clone"/>
    <origin rpy="-1.59000000e-03   1.59000000e-03   3.14159000e+00" xyz="0      -0.115   -0.00018"/>
    <axis xyz="-0.99999  0      -0.00159"/>
    <limit effort="-1.0" lower="-1.79769e+308" upper="1.79769e+308" velocity="-1.0"/>
  </joint>
  <link name="trial_noovy2__link_0">
    <inertial>
      <mass value="1"/>
      <origin rpy="0  0  0" xyz="0  0  0"/>
      <inertia ixx="0.166667" ixy="0" ixz="0" iyy="0.166667" iyz="0" izz="0.166667"/>
    </inertial>
    <collision name="trial_noovy2__collision">
      <origin rpy="0  0  0" xyz="0  0  0"/>
      <geometry>
        <mesh filename="/home/moovy_ws/src/demo_car/meshes/base_link.stl" scale="1 1 1"/>
      </geometry>
    </collision>
    <visual name="trial_noovy2__visual">
      <origin rpy="0  0  0" xyz="0  0  0"/>
      <geometry>
        <mesh filename="/home/subham/models/trials/base_link.stl" scale="1 1 1"/>
      </geometry>
    </visual>
  </link>
  <link name="trial_noovy2__link_1">
    <inertial>
      <mass value="1"/>
      <origin rpy="0  0  0" xyz="0  0  0"/>
      <inertia ixx="0.166667" ixy="0" ixz="0" iyy="0.166667" iyz="0" izz="0.166667"/>
    </inertial>
    <collision name="trial_noovy2__collision">
      <origin rpy="0  0  0" xyz="0    -0.115  0"/>
      <geometry>
        <mesh filename="/home/subham/models/trials/wheel_fr.stl" scale="1 1 1"/>
      </geometry>
    </collision>
    <visual name="trial_noovy2__visual">
      <origin rpy="0  0  0" xyz="0    -0.115  0"/>
      <geometry>
        <mesh filename="/home/subham/models/trials/wheel_fr.stl" scale="1 1 1"/>
      </geometry>
    </visual>
  </link>
  <link name="trial_noovy2__link_1_clone">
    <inertial>
      <mass value="1"/>
      <origin rpy="0  0  0" xyz="0  0  0"/>
      <inertia ixx="0.166667" ixy="0" ixz="0" iyy="0.166667" iyz="0" izz="0.166667"/>
    </inertial>
    <collision name="trial_noovy2__collision">
      <origin rpy="0  0  0" xyz="0    -0.115  0"/>
      <geometry>
        <mesh filename="/home/subham/models/trials/wheel_fr.stl" scale="1 1 1"/>
      </geometry>
    </collision>
    <visual name="trial_noovy2__visual">
      <origin rpy="0  0  0" xyz="0    -0.115  0"/>
      <geometry>
        <mesh filename="/home/subham/models/trials/wheel_fr.stl" scale="1 1 1"/>
      </geometry>
    </visual>
  </link>
  <link name="trial_noovy2__link_1_clone_clone">
    <inertial>
      <mass value="1"/>
      <origin rpy="0  0  0" xyz="0  0  0"/>
      <inertia ixx="0.166667" ixy="0" ixz="0" iyy="0.166667" iyz="0" izz="0.166667"/>
    </inertial>
    <collision name="trial_noovy2__collision">
      <origin rpy="0  0  0" xyz="0    -0.115  0"/>
      <geometry>
        <mesh filename="/home/subham/models/trials/wheel_fr.stl" scale="1 1 1"/>
      </geometry>
    </collision>
    <visual name="trial_noovy2__visual">
      <origin rpy="0  0  0" xyz="0    -0.115  0"/>
      <geometry>
        <mesh filename="/home/subham/models/trials/wheel_fr.stl" scale="1 1 1"/>
      </geometry>
    </visual>
  </link>
  <link name="trial_noovy2__link_1_clone_clone_clone">
    <inertial>
      <mass value="1"/>
      <origin rpy="0  0  0" xyz="0  0  0"/>
      <inertia ixx="0.166667" ixy="0" ixz="0" iyy="0.166667" iyz="0" izz="0.166667"/>
    </inertial>
    <collision name="trial_noovy2__collision">
      <origin rpy="0  0  0" xyz="0    -0.115  0"/>
      <geometry>
        <mesh filename="/home/subham/models/trials/wheel_fr.stl" scale="1 1 1"/>
      </geometry>
    </collision>
    <visual name="trial_noovy2__visual">
      <origin rpy="0  0  0" xyz="0    -0.115  0"/>
      <geometry>
        <mesh filename="/home/subham/models/trials/wheel_fr.stl" scale="1 1 1"/>
      </geometry>
    </visual>
  </link>
<gazebo>
  <plugin name="skid_steer_drive_controller" filename="libgazebo_ros_skid_steer_drive.so">
    <updateRate>100.0</updateRate>
    <robotNamespace>/</robotNamespace>
    <leftFrontJoint>trial_noovy2__link_0_JOINT_2</leftFrontJoint>
    <rightFrontJoint>trial_noovy2__link_0_JOINT_0</rightFrontJoint>
    <leftRearJoint>trial_noovy2__link_0_JOINT_4</leftRearJoint>
    <rightRearJoint>trial_noovy2__link_0_JOINT_3</rightRearJoint>
    <wheelSeparation>0.212</wheelSeparation>
    <wheelDiameter>0.01</wheelDiameter>
    <robotBaseFrame>trial_noovy2__link_0</robotBaseFrame>
    <torque>0.5</torque>
    <topicName>cmd_vel</topicName>
    <broadcastTF>false</broadcastTF>
  </plugin>
</gazebo>
</robot>
