<?xml version="1.0" encoding="utf-8"?>
<!-- =================================================================================== -->
<!-- |    This document was autogenerated by xacro from demo_car://robots/model1_t.urdf.xacro | -->
<!-- |    EDITING THIS FILE BY HAND IS NOT RECOMMENDED                                 | -->
<!-- =================================================================================== -->
<robot name="model" xmlns:controller="http://playerstage.sourceforge.net/gazebo/xmlschema/#controller" xmlns:interface="http://playerstage.sourceforge.net/gazebo/xmlschema/#interface" xmlns:sensor="http://playerstage.sourceforge.net/gazebo/xmlschema/#sensor" xmlns:xacro="http://ros.org/wiki/xacro">
  <joint name="model__link_0_JOINT_0" type="revolute">
    <parent link="model__link_0"/>
    <child link="model__link_1"/>
    <origin rpy="0  0  0" xyz="-3.00000000e-05   9.57100000e-02  -9.19500000e-02"/>
    <axis xyz="1  0  0"/>
    <limit effort="-1.0" lower="-1.79769e+308" upper="1.79769e+308" velocity="-1.0"/>
  </joint>
  <joint name="model__link_0_JOINT_1" type="revolute">
    <parent link="model__link_0"/>
    <child link="model__link_2"/>
    <origin rpy="3.14159000e+00   1.59000000e-03   3.14159000e+00" xyz="-3.00000000e-05   9.57100000e-02  -9.19500000e-02"/>
    <axis xyz="-0.99999  0       0.00159"/>
    <limit effort="-1.0" lower="-1.79769e+308" upper="1.79769e+308" velocity="-1.0"/>
  </joint>
  <joint name="model__link_0_JOINT_2" type="revolute">
    <parent link="model__link_0"/>
    <child link="model__link_3"/>
    <origin rpy="3.14  0    0" xyz="-3.00000000e-05  -1.34280000e-01  -9.17700000e-02"/>
    <axis xyz="1  0  0"/>
    <limit effort="-1.0" lower="-1.79769e+308" upper="1.79769e+308" velocity="-1.0"/>
  </joint>
  <joint name="model__link_0_JOINT_3" type="revolute">
    <parent link="model__link_0"/>
    <child link="model__link_4"/>
    <origin rpy="-1.59000000e-03   1.59000000e-03   3.14159000e+00" xyz="-3.00000000e-05  -1.34280000e-01  -9.21300000e-02"/>
    <axis xyz="-0.99999  0      -0.00159"/>
    <limit effort="-1.0" lower="-1.79769e+308" upper="1.79769e+308" velocity="-1.0"/>
  </joint>
  <link name="model__link_0">
   
    <collision name="model__collision">
      <origin rpy="0  0  0" xyz="-3.00000000e-05  -1.92800000e-02  -9.19500000e-02"/>
      <geometry>
        <mesh filename="demo_car://meshes/base_full.stl" scale="1 1 1"/>
      </geometry>
    </collision>
    <visual name="model__visual">
      <origin rpy="0  0  0" xyz="-3.00000000e-05  -1.92800000e-02  -9.19500000e-02"/>
      <geometry>
        <mesh filename="demo_car://meshes/base_full.stl" scale="1 1 1"/>
      </geometry>
    </visual>
  </link>
  <link name="model__link_1">
    <inertial>
      <mass value="1"/>
      <origin rpy="0  0  0" xyz="0  0  0"/>
      <inertia ixx="0.166667" ixy="0" ixz="0" iyy="0.166667" iyz="0" izz="0.166667"/>
    </inertial>
    <collision name="model__collision">
      <origin rpy="0  0  0" xyz="0    -0.115  0"/>
      <geometry>
        <mesh filename="demo_car://meshes/wheel_fr.stl" scale="1 1 1"/>
      </geometry>
    </collision>
    <visual name="model__visual">
      <origin rpy="0  0  0" xyz="0    -0.115  0"/>
      <geometry>
        <mesh filename="demo_car://meshes/wheel_fr.stl" scale="1 1 1"/>
      </geometry>
    </visual>
  </link>
  <link name="model__link_2">
    <inertial>
      <mass value="1"/>
      <origin rpy="0  0  0" xyz="0  0  0"/>
      <inertia ixx="0.166667" ixy="0" ixz="0" iyy="0.166667" iyz="0" izz="0.166667"/>
    </inertial>
    <collision name="model__collision">
      <origin rpy="0  0  0" xyz="0    -0.115  0"/>
      <geometry>
        <mesh filename="demo_car://meshes/wheel_fr.stl" scale="1 1 1"/>
      </geometry>
    </collision>
    <visual name="model__visual">
      <origin rpy="0  0  0" xyz="0    -0.115  0"/>
      <geometry>
        <mesh filename="demo_car://meshes/wheel_fr.stl" scale="1 1 1"/>
      </geometry>
    </visual>
  </link>
  <link name="model__link_3">
    <inertial>
      <mass value="1"/>
      <origin rpy="0  0  0" xyz="0  0  0"/>
      <inertia ixx="0.166667" ixy="0" ixz="0" iyy="0.166667" iyz="0" izz="0.166667"/>
    </inertial>
    <collision name="model__collision">
      <origin rpy="0  0  0" xyz="0    -0.115  0"/>
      <geometry>
        <mesh filename="demo_car://meshes/wheel_fr.stl" scale="1 1 1"/>
      </geometry>
    </collision>
    <visual name="model__visual">
      <origin rpy="0  0  0" xyz="0    -0.115  0"/>
      <geometry>
        <mesh filename="demo_car://meshes/wheel_fr.stl" scale="1 1 1"/>
      </geometry>
    </visual>
  </link>
  <link name="model__link_4">
    <inertial>
      <mass value="1"/>
      <origin rpy="0  0  0" xyz="0  0  0"/>
      <inertia ixx="0.166667" ixy="0" ixz="0" iyy="0.166667" iyz="0" izz="0.166667"/>
    </inertial>
    <collision name="model__collision">
      <origin rpy="0  0  0" xyz="0    -0.115  0"/>
      <geometry>
        <mesh filename="demo_car://meshes/wheel_fr.stl" scale="1 1 1"/>
      </geometry>
    </collision>
    <visual name="model__visual">
      <origin rpy="0  0  0" xyz="0    -0.115  0"/>
      <geometry>
        <mesh filename="demo_car://meshes/wheel_fr.stl" scale="1 1 1"/>
      </geometry>
    </visual>
  </link>


  <joint name="camera_camera_joint1" type="fixed">
    <origin rpy="0 -1.60 0" xyz="0.045842 0.004845 0.089453"/>
    <parent link="model__link_0"/>
    <child link="camera_camera1"/>
  </joint>
  <link name="camera_camera1">
    <inertial>
      <mass value="0.01"/>
      <origin xyz="0 0 0"/>
      <inertia ixx="0.001" ixy="0.0" ixz="0.0" iyy="0.001" iyz="0.0" izz="0.001"/>
    </inertial>
    <visual>
      <origin rpy="1.57 -1.57 3.14" xyz="0.61 0.035 0.025"/>
      <geometry>
        <mesh filename="demo_car://meshes/sensors/microsoft_lifecam.dae" scale="0.001 0.001 0.001"/>
      </geometry>
    </visual>
    <collision>
      <origin rpy="1.57 -1.57 3.14" xyz="0.61 0.035 0.025"/>
      <geometry>
        <mesh filename="demo_car://meshes/sensors/microsoft_lifecam.dae" scale="0.001 0.001 0.001"/>
      </geometry>
    </collision>
  </link>

  <gazebo reference="camera_camera1">
    <material>Gazebo/Black</material>
    <sensor type="camera" name="camera1">
      <update_rate>30.0</update_rate>
      <camera name="head">
        
<pose>0.6465 0.065 0.02648 1.57 0 1.57</pose>
        <image>
          <width>1920</width>
          <height>1080</height>
          <format>R8G8B8</format>
        </image>
        <clip>
          <near>0.01</near>
          <far>300</far>
        </clip>
      </camera>
      <plugin name="camera_controller" filename="libgazebo_ros_camera.so">
        <alwaysOn>true</alwaysOn>
        <updateRate>0.0</updateRate>
        <cameraName>mybot/camera1</cameraName>
        <imageTopicName>image_raw</imageTopicName>
        <cameraInfoTopicName>camera_info</cameraInfoTopicName>
        <frameName>camera_camera1</frameName>
        <hackBaseline>0.07</hackBaseline>
        <distortionK1>0.0</distortionK1>
        <distortionK2>0.0</distortionK2>
        <distortionK3>0.0</distortionK3>
        <distortionT1>0.0</distortionT1>
        <distortionT2>0.0</distortionT2>
      </plugin>
    </sensor>
  </gazebo>

  <link name="camera_foot_link">
    <inertial>
      <mass value="0.0005"/>
      <origin rpy="0 0 0" xyz="0 0 0"/>
      <inertia ixx="0.0001" ixy="0" ixz="0" iyy="0.0001" iyz="0" izz="0.0001"/>
    </inertial>
    <visual>
      <origin rpy="1.57 0 1.57" xyz="0.01 0 0"/>
      <geometry>
        <mesh filename="demo_car://meshes/sensors/asus_xtion_pro_live_base.dae" scale="0.0004 0.0007 0.001"/>
      </geometry>
      <material name="Black"/>
    </visual>
    <collision>
      <origin rpy="1.57 0 1.57" xyz="0.01 0 0"/>
      <geometry>
        <mesh filename="demo_car://meshes/sensors/asus_xtion_pro_live_base.dae" scale="0.0004 0.0007 0.001"/>
      </geometry>
    </collision>
  </link>
  <joint name="camera_foot_joint" type="fixed">
    <origin rpy="0 -1.60 0" xyz="-0.02 0 -0.04"/>
    <parent link="model__link_0"/>
    <child link="camera_foot_link"/>
  </joint>
  <link name="camera_tilt_link">
    <inertial>
      <mass value="0.0001"/>
      <origin rpy="0 0 0" xyz="0 0 0"/>
      <inertia ixx="0.0001" ixy="0" ixz="0" iyy="0.0001" iyz="0" izz="0.0001"/>
    </inertial>
    <visual>
      <origin rpy="0 0 0" xyz="0 0 0.0075"/>
      <geometry>
        <cylinder length="0.025" radius="0.005"/>
      </geometry>
      <material name="Black"/>
    </visual>
    <collision>
      <origin rpy="0 0 0" xyz="0 0 0.0075"/>
      <geometry>
        <cylinder length="0.025" radius="0.005"/>
      </geometry>
      <material name="Black"/>
    </collision>
  </link>
  <joint name="asus_xtion_tilt_joint" type="fixed">
    <parent link="camera_foot_link"/>
    <child link="camera_tilt_link"/>
    <!--<axis xyz="0 1 0"/>-->
    <origin rpy="-1.57 3.14 -1.57" xyz="0.46 0.02 -0.03"/>
    <!--<limit effort="100" lower="-0.541052068" upper="0.541052068" velocity="1.0"/>-->
  </joint>
  <link name="camera_camera">
    <inertial>
      <mass value="0.001"/>
      <origin rpy="0 0 0" xyz="0 0 0"/>
      <inertia ixx="0.0001" ixy="0" ixz="0" iyy="0.0001" iyz="0" izz="0.0001"/>
    </inertial>
    <visual>
      <origin rpy="1.57 0 1.57" xyz="0.02 -0.03 0"/>
      <geometry>
        <mesh filename="demo_car://meshes/sensors/asus_xtion_pro_live_camera.dae" scale="0.001 0.001 0.001"/>
      </geometry>
      <material name="Black"/>
    </visual>
    <collision>
      <origin rpy="1.57 0 1.57" xyz="0.02 -0.03 0"/>
      <geometry>
        <mesh filename="demo_car://meshes/sensors/asus_xtion_pro_live_camera.dae" scale="0.001 0.001 0.001"/>
      </geometry>
    </collision>
  </link>
  <joint name="camera_camera_joint" type="fixed">
    <origin rpy="0 0 0" xyz="0 0.03 0.03"/>
    <parent link="camera_tilt_link"/>
    <child link="camera_camera"/>
  </joint>
  <link name="camera_depth_frame">
    <inertial>
      <mass value="0.0001"/>
      <origin xyz="0 0 0"/>
      <inertia ixx="0.1" ixy="0" ixz="0" iyy="0.1" iyz="0" izz="0.1"/>
    </inertial>
  </link>
  <joint name="camera_depth_joint" type="fixed">
    <parent link="camera_camera"/>
    <child link="camera_depth_frame"/>
    <origin rpy="0 0 0" xyz="0.03 0.015 0"/>
  </joint>
  <link name="camera_depth_optical_frame">
    <inertial>
      <mass value="0.0001"/>
      <origin xyz="0 0 0"/>
      <inertia ixx="0.1" ixy="0" ixz="0" iyy="0.1" iyz="0" izz="0.1"/>
    </inertial>
  </link>
  <joint name="camera_depth_optical_joint" type="fixed">
    <parent link="camera_camera"/>
    <child link="camera_depth_optical_frame"/>
    <origin rpy="-1.57 0 -1.57" xyz="0.03 0.015 0"/>
  </joint>
  <link name="camera_rgb_frame">
    <inertial>
      <mass value="0.0001"/>
      <origin xyz="0 0 0"/>
      <inertia ixx="0.1" ixy="0" ixz="0" iyy="0.1" iyz="0" izz="0.1"/>
    </inertial>
  </link>
  <joint name="camera_rgb_joint" type="fixed">
    <parent link="camera_camera"/>
    <child link="camera_rgb_frame"/>
    <origin rpy="0 0 0" xyz="0.03 -0.005 0"/>
  </joint>
  <link name="camera_rgb_optical_frame">
    <inertial>
      <mass value="0.0001"/>
      <origin xyz="0 0 0"/>
      <inertia ixx="0.1" ixy="0" ixz="0" iyy="0.1" iyz="0" izz="0.1"/>
    </inertial>
  </link>
  <joint name="camera_rgb_optical_joint" type="fixed">
    <parent link="camera_camera"/>
    <child link="camera_rgb_optical_frame"/>
    <origin rpy="-1.57 0 -1.57" xyz="0.03 -0.005 0"/>
  </joint>
  <link name="camera_laser_frame">
    <inertial>
      <mass value="0.0001"/>
      <origin xyz="0 0 0"/>
      <inertia ixx="0.1" ixy="0" ixz="0" iyy="0.1" iyz="0" izz="0.1"/>
    </inertial>
  </link>
  <joint name="camera_laser_joint" type="fixed">
    <parent link="camera_camera"/>
    <child link="camera_laser_frame"/>
    <origin rpy="0 0 0" xyz="0.03 -0.055 0"/>
  </joint>
  <link name="camera_laser_optical_frame">
    <inertial>
      <mass value="0.0001"/>
      <origin xyz="0 0 0"/>
      <inertia ixx="0.1" ixy="0" ixz="0" iyy="0.1" iyz="0" izz="0.1"/>
    </inertial>
  </link>
  <joint name="camera_laser_optical_joint" type="fixed">
    <parent link="camera_camera"/>
    <child link="camera_laser_optical_frame"/>
    <origin rpy="1.57 0 -1.57" xyz="0.03 -0.055 0"/>
  </joint>
  <gazebo reference="camera_camera">
    <sensor name="camera_depth_frame_sensor" type="depth">
      <always_on>true</always_on>
      <update_rate>20.0</update_rate>
      <camera>
        <horizontal_fov>0.994333333333</horizontal_fov>
        <image>
          <format>R8G8B8</format>
          <width>640</width>
          <height>480</height>
        </image>
        <clip>
          <near>0.05</near>
          <far>5</far>
        </clip>
      </camera>
      <plugin filename="libgazebo_ros_openni_kinect.so" name="camera_depth_frame_controller">
        <baseline>0.2</baseline>
        <alwaysOn>true</alwaysOn>
        <updateRate>20.0</updateRate>
        <cameraName>camera_depth</cameraName>
        <cameraName>camera_rgb</cameraName>
        <imageTopicName>/camera/rgb/image_raw</imageTopicName>
        <cameraInfoTopicName>/camera/rgb/camera_info</cameraInfoTopicName>
      <!--imageTopicName>/${name}/ir/image_raw</imageTopicName>
      <cameraInfoTopicName>/${name}/ir/camera_info</cameraInfoTopicName-->
        <depthImageTopicName>/camera/depth/image_raw</depthImageTopicName>
        <depthImageCameraInfoTopicName>/camera/depth/camera_info</depthImageCameraInfoTopicName>
        <pointCloudTopicName>/camera/depth/points</pointCloudTopicName>
        <frameName>camera_depth_optical_frame</frameName>
        <pointCloudCutoff>0.5</pointCloudCutoff>
        <distortionK1>0.00000001</distortionK1>
        <distortionK2>0.00000001</distortionK2>
        <distortionK3>0.00000001</distortionK3>
        <distortionT1>0.00000001</distortionT1>
        <distortionT2>0.00000001</distortionT2>
        <CxPrime>0</CxPrime>
        <Cx>0</Cx>
        <Cy>0</Cy>
        <focalLength>0</focalLength>
        <hackBaseline>0</hackBaseline>
      </plugin>
    </sensor>
    <!--
  <sensor type="depth" name="${name}_rgb_frame_sensor">    
    <always_on>true</always_on>
    <update_rate>20.0</update_rate>
    <camera>
      <horizontal_fov>${57.0*3.14/180.0}</horizontal_fov>
      <image>
        <format>R8G8B8</format>
        <width>640</width>
        <height>480</height>
      </image>
      <clip>
        <near>0.1</near>
        <far>5</far>
      </clip>
    </camera>
    <plugin name="${name}_rgb_frame_controller" filename="libgazebo_ros_openni_kinect.so">
      <baseline>0.2</baseline>
      <alwaysOn>true</alwaysOn>
      <updateRate>20.0</updateRate>
      <cameraName>${name}_rgb</cameraName>
      <imageTopicName>/${name}/rgb/image_raw</imageTopicName>
      <cameraInfoTopicName>/${name}/rgb/camera_info</cameraInfoTopicName>
      <depthImageTopicName>/${name}/depth_registered/image_raw</depthImageTopicName>
      <depthImageCameraInfoTopicName>/${name}/depth_registered/camera_info</depthImageCameraInfoTopicName>
      <pointCloudTopicName>/${name}/depth_registered/points</pointCloudTopicName>
      <frameName>${name}_rgb_optical_frame</frameName>
      <pointCloudCutoff>0.5</pointCloudCutoff>
      <distortionK1>0.00000001</distortionK1>
      <distortionK2>0.00000001</distortionK2>
      <distortionK3>0.00000001</distortionK3>
      <distortionT1>0.00000001</distortionT1>
      <distortionT2>0.00000001</distortionT2>
      <CxPrime>0</CxPrime>
      <Cx>0</Cx>
      <Cy>0</Cy>
      <focalLength>0</focalLength>
      <hackBaseline>0</hackBaseline>
    </plugin>
  </sensor>
-->
  </gazebo>
  <gazebo>
    <plugin filename="libgazebo_ros_skid_steer_drive.so" name="skid_steer_drive_controller">
      <updateRate>100.0</updateRate>
      <robotNamespace>/</robotNamespace>
      <leftFrontJoint>model__link_0_JOINT_1</leftFrontJoint>
      <rightFrontJoint>model__link_0_JOINT_0</rightFrontJoint>
      <leftRearJoint>model__link_0_JOINT_3</leftRearJoint>
      <rightRearJoint>model__link_0_JOINT_2</rightRearJoint>
      <wheelSeparation>0.212</wheelSeparation>
      <wheelDiameter>0.01</wheelDiameter>
      <robotBaseFrame>model__link_0</robotBaseFrame>
      <torque>0.5</torque>
      <topicName>cmd_vel</topicName>
      <broadcastTF>false</broadcastTF>
    </plugin>
  </gazebo>
  
</robot>


