<?xml version="1.0" encoding="utf-8"?>
<!-- =================================================================================== -->
<!-- |    This document was autogenerated by xacro from /home/pratik/review4/src/demo_car/robots/model1_t.urdf.xacro | -->
<!-- |    EDITING THIS FILE BY HAND IS NOT RECOMMENDED                                 | -->
<!-- =================================================================================== -->
<robot name="model" xmlns:xacro="http://ros.org/wiki/xacro">
  <joint name="model__link_0_JOINT_0" type="revolute">
    <parent link="model__link_0"/>
    <child link="model__link_1"/>
    <origin rpy="0  0  0" xyz="-3.00000000e-05   9.57100000e-02  -9.19500000e-02"/>
    <axis xyz="1  0  0"/>
    <limit effort="-1.0" lower="-1.79769e+308" upper="1.79769e+308" velocity="-1.0"/>
  </joint>
  <joint name="model__link_0_JOINT_1" type="revolute">
    <parent link="model__link_0"/>
    <child link="model__link_2"/>
    <origin rpy="3.14159000e+00   1.59000000e-03   3.14159000e+00" xyz="-3.00000000e-05   9.57100000e-02  -9.19500000e-02"/>
    <axis xyz="-0.99999  0       0.00159"/>
    <limit effort="-1.0" lower="-1.79769e+308" upper="1.79769e+308" velocity="-1.0"/>
  </joint>
  <joint name="model__link_0_JOINT_2" type="revolute">
    <parent link="model__link_0"/>
    <child link="model__link_3"/>
    <origin rpy="3.14  0    0" xyz="-3.00000000e-05  -1.34280000e-01  -9.17700000e-02"/>
    <axis xyz="1  0  0"/>
    <limit effort="-1.0" lower="-1.79769e+308" upper="1.79769e+308" velocity="-1.0"/>
  </joint>
  <joint name="model__link_0_JOINT_3" type="revolute">
    <parent link="model__link_0"/>
    <child link="model__link_4"/>
    <origin rpy="-1.59000000e-03   1.59000000e-03   3.14159000e+00" xyz="-3.00000000e-05  -1.34280000e-01  -9.21300000e-02"/>
    <axis xyz="-0.99999  0      -0.00159"/>
    <limit effort="-1.0" lower="-1.79769e+308" upper="1.79769e+308" velocity="-1.0"/>
  </joint>
  <link name="model__link_0">
    <inertial>
      <mass value="1"/>
      <origin rpy="0  0  0" xyz="0  0  0"/>
      <inertia ixx="0.166667" ixy="0" ixz="0" iyy="0.166667" iyz="0" izz="0.166667"/>
    </inertial>
    <collision name="model__collision">
      <origin rpy="0  0  0" xyz="-3.00000000e-05  -1.92800000e-02  -9.19500000e-02"/>
      <geometry>
        <mesh filename="/home/pratik/review4/src/demo_car/meshes/base_full.stl" scale="1 1 1"/>
      </geometry>
    </collision>
    <visual name="model__visual">
      <origin rpy="0  0  0" xyz="-3.00000000e-05  -1.92800000e-02  -9.19500000e-02"/>
      <geometry>
        <mesh filename="/home/pratik/review4/src/demo_car/meshes/base_full.stl" scale="1 1 1"/>
      </geometry>
    </visual>
  </link>
  <link name="model__link_1">
    <inertial>
      <mass value="1"/>
      <origin rpy="0  0  0" xyz="0  0  0"/>
      <inertia ixx="0.166667" ixy="0" ixz="0" iyy="0.166667" iyz="0" izz="0.166667"/>
    </inertial>
    <collision name="model__collision">
      <origin rpy="0  0  0" xyz="0    -0.115  0"/>
      <geometry>
        <mesh filename="/home/pratik/review4/src/demo_car/meshes/wheel_fr.stl" scale="1 1 1"/>
      </geometry>
    </collision>
    <visual name="model__visual">
      <origin rpy="0  0  0" xyz="0    -0.115  0"/>
      <geometry>
        <mesh filename="/home/pratik/review4/src/demo_car/meshes/wheel_fr.stl" scale="1 1 1"/>
      </geometry>
    </visual>
  </link>
  <link name="model__link_2">
    <inertial>
      <mass value="1"/>
      <origin rpy="0  0  0" xyz="0  0  0"/>
      <inertia ixx="0.166667" ixy="0" ixz="0" iyy="0.166667" iyz="0" izz="0.166667"/>
    </inertial>
    <collision name="model__collision">
      <origin rpy="0  0  0" xyz="0    -0.115  0"/>
      <geometry>
        <mesh filename="/home/pratik/review4/src/demo_car/meshes/wheel_fr.stl" scale="1 1 1"/>
      </geometry>
    </collision>
    <visual name="model__visual">
      <origin rpy="0  0  0" xyz="0    -0.115  0"/>
      <geometry>
        <mesh filename="/home/pratik/review4/src/demo_car/meshes/wheel_fr.stl" scale="1 1 1"/>
      </geometry>
    </visual>
  </link>
  <link name="model__link_3">
    <inertial>
      <mass value="1"/>
      <origin rpy="0  0  0" xyz="0  0  0"/>
      <inertia ixx="0.166667" ixy="0" ixz="0" iyy="0.166667" iyz="0" izz="0.166667"/>
    </inertial>
    <collision name="model__collision">
      <origin rpy="0  0  0" xyz="0    -0.115  0"/>
      <geometry>
        <mesh filename="/home/pratik/review4/src/demo_car/meshes/wheel_fr.stl" scale="1 1 1"/>
      </geometry>
    </collision>
    <visual name="model__visual">
      <origin rpy="0  0  0" xyz="0    -0.115  0"/>
      <geometry>
        <mesh filename="/home/pratik/review4/src/demo_car/meshes/wheel_fr.stl" scale="1 1 1"/>
      </geometry>
    </visual>
  </link>
  <link name="model__link_4">
    <inertial>
      <mass value="1"/>
      <origin rpy="0  0  0" xyz="0  0  0"/>
      <inertia ixx="0.166667" ixy="0" ixz="0" iyy="0.166667" iyz="0" izz="0.166667"/>
    </inertial>
    <collision name="model__collision">
      <origin rpy="0  0  0" xyz="0    -0.115  0"/>
      <geometry>
        <mesh filename="/home/pratik/review4/src/demo_car/meshes/wheel_fr.stl" scale="1 1 1"/>
      </geometry>
    </collision>
    <visual name="model__visual">
      <origin rpy="0  0  0" xyz="0    -0.115  0"/>
      <geometry>
        <mesh filename="/home/pratik/review4/src/demo_car/meshes/wheel_fr.stl" scale="1 1 1"/>
      </geometry>
    </visual>
  </link>
  <joint name="laser_front_hokuyo_urg04_laser_joint" type="fixed">
    <axis xyz="0 1 0"/>
    <origin rpy="0 0 0" xyz="0 0 0"/>
    <parent link="model__link_0"/>
    <child link="laser_front_link"/>
  </joint>
  <link name="laser_front_link" type="laser">
    <inertial>
      <mass value="0.16"/>
      <origin rpy="0 0 0" xyz="0.045842 0.004845 0.089453"/>
      <inertia ixx="0.1" ixy="0" ixz="0" iyy="0.1" iyz="0" izz="0.1"/>
    </inertial>
    <visual>
      <origin rpy="0 0 0" xyz="0.045842 0.004845 0.089453"/>
      <geometry>
        <mesh filename="package://demo_car/meshes/sensors/hokuyo.dae"/>
      </geometry>
    </visual>
    <collision>
      <origin rpy="0 0 0" xyz="0 0 0"/>
      <geometry>
        <mesh filename="package://demo_car/meshes/sensors/hokuyo_convex.dae"/>
      </geometry>
    </collision>
  </link>
  <gazebo reference="laser_front_link">
    <sensor name="laser_front" type="ray">
      <pose>0 0 0 0 0 0</pose>
      <ray>
        <scan>
          <horizontal>
            <samples>640</samples>
            <resolution>1</resolution>
            <min_angle>-1.570000</min_angle>
            <max_angle>1.570000</max_angle>
          </horizontal>
        </scan>
        <range>
          <min>0.050000</min>
          <max>5.600000</max>
          <resolution>0.360000</resolution>
        </range>
      </ray>
      <always_on>true</always_on>
      <update_rate>10</update_rate>
      <visualize>false</visualize>
      <plugin filename="libgazebo_ros_laser.so" name="gazebo_ros_laser">
        <gaussianNoise>0.02</gaussianNoise>
        <alwaysOn>true</alwaysOn>
        <hokuyoMinIntensity>101</hokuyoMinIntensity>
        <updateRate>10</updateRate>
        <topicName>scan</topicName>
        <frameName>/laser_front_link</frameName>
        <!--interface:laser name="gazebo_ros_${name}_iface" /-->
      </plugin>
    </sensor>
  </gazebo>
  <gazebo>
    <plugin filename="libgazebo_ros_skid_steer_drive.so" name="skid_steer_drive_controller">
      <updateRate>100.0</updateRate>
      <robotNamespace>/</robotNamespace>
      <leftFrontJoint>model__link_0_JOINT_1</leftFrontJoint>
      <rightFrontJoint>model__link_0_JOINT_0</rightFrontJoint>
      <leftRearJoint>model__link_0_JOINT_3</leftRearJoint>
      <rightRearJoint>model__link_0_JOINT_2</rightRearJoint>
      <wheelSeparation>0.212</wheelSeparation>
      <wheelDiameter>0.01</wheelDiameter>
      <robotBaseFrame>model__link_0</robotBaseFrame>
      <torque>0.5</torque>
      <topicName>cmd_vel</topicName>
      <broadcastTF>false</broadcastTF>
    </plugin>
  </gazebo>
  <gazebo>
    <plugin filename="libTeleopTwistJoyPlugin.so" name="teleop_twist_joy">
      <input_topic>/joy</input_topic>
      <output_topic>/cmd_vel</output_topic>
      <enable_button>10</enable_button>
      <axis_linear>3</axis_linear>
      <scale_linear>1.0</scale_linear>
      <axis_angular>0</axis_angular>
      <scale_angular>1.0</scale_angular>
    </plugin>
  </gazebo>
</robot>

