<?xml version="1.0" encoding="utf-8"?>
<!-- =================================================================================== -->
<!-- |    This document was autogenerated by xacro from /home/pratik/review4/src/demo_car/robots/model1_t.urdf.xacro | -->
<!-- |    EDITING THIS FILE BY HAND IS NOT RECOMMENDED                                 | -->
<!-- =================================================================================== -->
<robot name="model" xmlns:controller="http://playerstage.sourceforge.net/gazebo/xmlschema/#controller" xmlns:interface="http://playerstage.sourceforge.net/gazebo/xmlschema/#interface" xmlns:sensor="http://playerstage.sourceforge.net/gazebo/xmlschema/#sensor" xmlns:xacro="http://ros.org/wiki/xacro">
  <joint name="model__link_0_JOINT_0" type="revolute">
    <parent link="model__link_0"/>
    <child link="model__link_1"/>
    <origin rpy="0  0  0" xyz="-3.00000000e-05   9.57100000e-02  -9.19500000e-02"/>
    <axis xyz="1  0  0"/>
    <limit effort="-1.0" lower="-1.79769e+308" upper="1.79769e+308" velocity="-1.0"/>
  </joint>
  <joint name="model__link_0_JOINT_1" type="revolute">
    <parent link="model__link_0"/>
    <child link="model__link_2"/>
    <origin rpy="3.14159000e+00   1.59000000e-03   3.14159000e+00" xyz="-3.00000000e-05   9.57100000e-02  -9.19500000e-02"/>
    <axis xyz="-0.99999  0       0.00159"/>
    <limit effort="-1.0" lower="-1.79769e+308" upper="1.79769e+308" velocity="-1.0"/>
  </joint>
  <joint name="model__link_0_JOINT_2" type="revolute">
    <parent link="model__link_0"/>
    <child link="model__link_3"/>
    <origin rpy="3.14  0    0" xyz="-3.00000000e-05  -1.34280000e-01  -9.17700000e-02"/>
    <axis xyz="1  0  0"/>
    <limit effort="-1.0" lower="-1.79769e+308" upper="1.79769e+308" velocity="-1.0"/>
  </joint>
  <joint name="model__link_0_JOINT_3" type="revolute">
    <parent link="model__link_0"/>
    <child link="model__link_4"/>
    <origin rpy="-1.59000000e-03   1.59000000e-03   3.14159000e+00" xyz="-3.00000000e-05  -1.34280000e-01  -9.21300000e-02"/>
    <axis xyz="-0.99999  0      -0.00159"/>
    <limit effort="-1.0" lower="-1.79769e+308" upper="1.79769e+308" velocity="-1.0"/>
  </joint>
  <link name="model__link_0">
    <inertial>
      <mass value="1"/>
      <origin rpy="0  0  0" xyz="0  0  0"/>
      <inertia ixx="0.166667" ixy="0" ixz="0" iyy="0.166667" iyz="0" izz="0.166667"/>
    </inertial>
    <collision name="model__collision">
      <origin rpy="0  0  0" xyz="-3.00000000e-05  -1.92800000e-02  -9.19500000e-02"/>
      <geometry>
        <mesh filename="/home/pratik/review4/src/demo_car/meshes/base_full.stl" scale="1 1 1"/>
      </geometry>
    </collision>
    <visual name="model__visual">
      <origin rpy="0  0  0" xyz="-3.00000000e-05  -1.92800000e-02  -9.19500000e-02"/>
      <geometry>
        <mesh filename="/home/pratik/review4/src/demo_car/meshes/base_full.stl" scale="1 1 1"/>
      </geometry>
    </visual>
  </link>
  <link name="model__link_1">
    <inertial>
      <mass value="1"/>
      <origin rpy="0  0  0" xyz="0  0  0"/>
      <inertia ixx="0.166667" ixy="0" ixz="0" iyy="0.166667" iyz="0" izz="0.166667"/>
    </inertial>
    <collision name="model__collision">
      <origin rpy="0  0  0" xyz="0    -0.115  0"/>
      <geometry>
        <mesh filename="/home/pratik/review4/src/demo_car/meshes/wheel_fr.stl" scale="1 1 1"/>
      </geometry>
    </collision>
    <visual name="model__visual">
      <origin rpy="0  0  0" xyz="0    -0.115  0"/>
      <geometry>
        <mesh filename="/home/pratik/review4/src/demo_car/meshes/wheel_fr.stl" scale="1 1 1"/>
      </geometry>
    </visual>
  </link>
  <link name="model__link_2">
    <inertial>
      <mass value="1"/>
      <origin rpy="0  0  0" xyz="0  0  0"/>
      <inertia ixx="0.166667" ixy="0" ixz="0" iyy="0.166667" iyz="0" izz="0.166667"/>
    </inertial>
    <collision name="model__collision">
      <origin rpy="0  0  0" xyz="0    -0.115  0"/>
      <geometry>
        <mesh filename="/home/pratik/review4/src/demo_car/meshes/wheel_fr.stl" scale="1 1 1"/>
      </geometry>
    </collision>
    <visual name="model__visual">
      <origin rpy="0  0  0" xyz="0    -0.115  0"/>
      <geometry>
        <mesh filename="/home/pratik/review4/src/demo_car/meshes/wheel_fr.stl" scale="1 1 1"/>
      </geometry>
    </visual>
  </link>
  <link name="model__link_3">
    <inertial>
      <mass value="1"/>
      <origin rpy="0  0  0" xyz="0  0  0"/>
      <inertia ixx="0.166667" ixy="0" ixz="0" iyy="0.166667" iyz="0" izz="0.166667"/>
    </inertial>
    <collision name="model__collision">
      <origin rpy="0  0  0" xyz="0    -0.115  0"/>
      <geometry>
        <mesh filename="/home/pratik/review4/src/demo_car/meshes/wheel_fr.stl" scale="1 1 1"/>
      </geometry>
    </collision>
    <visual name="model__visual">
      <origin rpy="0  0  0" xyz="0    -0.115  0"/>
      <geometry>
        <mesh filename="/home/pratik/review4/src/demo_car/meshes/wheel_fr.stl" scale="1 1 1"/>
      </geometry>
    </visual>
  </link>
  <link name="model__link_4">
    <inertial>
      <mass value="1"/>
      <origin rpy="0  0  0" xyz="0  0  0"/>
      <inertia ixx="0.166667" ixy="0" ixz="0" iyy="0.166667" iyz="0" izz="0.166667"/>
    </inertial>
    <collision name="model__collision">
      <origin rpy="0  0  0" xyz="0    -0.115  0"/>
      <geometry>
        <mesh filename="/home/pratik/review4/src/demo_car/meshes/wheel_fr.stl" scale="1 1 1"/>
      </geometry>
    </collision>
    <visual name="model__visual">
      <origin rpy="0  0  0" xyz="0    -0.115  0"/>
      <geometry>
        <mesh filename="/home/pratik/review4/src/demo_car/meshes/wheel_fr.stl" scale="1 1 1"/>
      </geometry>
    </visual>
  </link>
  <gazebo reference="openni_camera">
    <sensor:camera name="openni_depth_frame_sensor">
      <imageFormat>R8G8B8</imageFormat>
      <imageSize>640 480</imageSize>
      <hfov>57</hfov>
      <nearClip>0.01</nearClip>
      <farClip>5</farClip>
      <updateRate>20.0</updateRate>
      <baseline>0.2</baseline>
      <controller:gazebo_ros_camera name="openni_depth_frame_controller" plugin="libgazebo_ros_camera.so">
        <alwaysOn>true</alwaysOn>
        <updateRate>20.0</updateRate>
        <imageTopicName>/camera/ir/image_raw</imageTopicName>
        <cameraInfoTopicName>/camera/ir/camera_info</cameraInfoTopicName>
        <depthImageTopicName>/camera/depth/image_raw</depthImageTopicName>
        <depthImageInfoTopicName>/camera/depth/camera_info</depthImageInfoTopicName>
        <pointCloudTopicName>/camera/depth/points</pointCloudTopicName>
        <frameName>/openni_depth_optical_frame</frameName>
        <pointCloudCutoff>0.5</pointCloudCutoff>
        <distortion_k1>0.00000001</distortion_k1>
        <distortion_k2>0.00000001</distortion_k2>
        <distortion_k3>0.00000001</distortion_k3>
        <distortion_t1>0.00000001</distortion_t1>
        <distortion_t2>0.00000001</distortion_t2>
      </controller:gazebo_ros_camera>
    </sensor:camera>
    <sensor:camera name="openni_rgb_frame_sensor">
      <imageFormat>R8G8B8</imageFormat>
      <imageSize>640 480</imageSize>
      <hfov>57</hfov>
      <nearClip>0.01</nearClip>
      <farClip>5</farClip>
      <updateRate>20.0</updateRate>
      <baseline>0.2</baseline>
      <controller:gazebo_ros_camera name="openni_rgb_frame_controller" plugin="libgazebo_ros_camera.so">
        <alwaysOn>true</alwaysOn>
        <updateRate>20.0</updateRate>
        <imageTopicName>/camera/rgb/image_raw</imageTopicName>
        <cameraInfoTopicName>/camera/rgb/camera_info</cameraInfoTopicName>
        <frameName>/openni_rgb_optical_frame</frameName>
        <pointCloudCutoff>0.5</pointCloudCutoff>
        <distortion_k1>0.00000001</distortion_k1>
        <distortion_k2>0.00000001</distortion_k2>
        <distortion_k3>0.00000001</distortion_k3>
        <distortion_t1>0.00000001</distortion_t1>
        <distortion_t2>0.00000001</distortion_t2>
      </controller:gazebo_ros_camera>
    </sensor:camera>
  </gazebo>
  <!--<xacro:kinect_camera name="openni" parent="model__link_0">
     			 <origin xyz="0.045842 0.004845 0.089453" rpy="0 0 0" />
    		</xacro:kinect_camera>-->
  <gazebo>
    <plugin filename="libgazebo_ros_skid_steer_drive.so" name="skid_steer_drive_controller">
      <updateRate>100.0</updateRate>
      <robotNamespace>/</robotNamespace>
      <leftFrontJoint>model__link_0_JOINT_1</leftFrontJoint>
      <rightFrontJoint>model__link_0_JOINT_0</rightFrontJoint>
      <leftRearJoint>model__link_0_JOINT_3</leftRearJoint>
      <rightRearJoint>model__link_0_JOINT_2</rightRearJoint>
      <wheelSeparation>0.212</wheelSeparation>
      <wheelDiameter>0.01</wheelDiameter>
      <robotBaseFrame>model__link_0</robotBaseFrame>
      <torque>0.5</torque>
      <topicName>cmd_vel</topicName>
      <broadcastTF>false</broadcastTF>
    </plugin>
  </gazebo>
  <gazebo>
    <plugin filename="libTeleopTwistJoyPlugin.so" name="teleop_twist_joy">
      <input_topic>/joy</input_topic>
      <output_topic>/cmd_vel</output_topic>
      <enable_button>10</enable_button>
      <axis_linear>3</axis_linear>
      <scale_linear>1.0</scale_linear>
      <axis_angular>0</axis_angular>
      <scale_angular>1.0</scale_angular>
    </plugin>
  </gazebo>
</robot>

