<?xml version="1.0" ?>
<robot name="model">
  <joint name="model__link_0_JOINT_0" type="revolute">
    <parent link="model__link_0"/>
    <child link="model__link_1"/>
    <origin rpy="0  0  0" xyz="-3.00000000e-05   9.57100000e-02  -9.19500000e-02"/>
    <axis xyz="1  0  0"/>
    <limit effort="-1.0" lower="-1.79769e+308" upper="1.79769e+308" velocity="-1.0"/>
  </joint>
  <joint name="model__link_0_JOINT_1" type="revolute">
    <parent link="model__link_0"/>
    <child link="model__link_2"/>
    <origin rpy="3.14159000e+00   1.59000000e-03   3.14159000e+00" xyz="-3.00000000e-05   9.57100000e-02  -9.19500000e-02"/>
    <axis xyz="-0.99999  0       0.00159"/>
    <limit effort="-1.0" lower="-1.79769e+308" upper="1.79769e+308" velocity="-1.0"/>
  </joint>
  <joint name="model__link_0_JOINT_2" type="revolute">
    <parent link="model__link_0"/>
    <child link="model__link_3"/>
    <origin rpy="3.14  0    0" xyz="-3.00000000e-05  -1.34280000e-01  -9.17700000e-02"/>
    <axis xyz="1  0  0"/>
    <limit effort="-1.0" lower="-1.79769e+308" upper="1.79769e+308" velocity="-1.0"/>
  </joint>
  <joint name="model__link_0_JOINT_3" type="revolute">
    <parent link="model__link_0"/>
    <child link="model__link_4"/>
    <origin rpy="-1.59000000e-03   1.59000000e-03   3.14159000e+00" xyz="-3.00000000e-05  -1.34280000e-01  -9.21300000e-02"/>
    <axis xyz="-0.99999  0      -0.00159"/>
    <limit effort="-1.0" lower="-1.79769e+308" upper="1.79769e+308" velocity="-1.0"/>
  </joint>
  <link name="model__link_0">
    <inertial>
      <mass value="1"/>
      <origin rpy="0  0  0" xyz="0  0  0"/>
      <inertia ixx="0.166667" ixy="0" ixz="0" iyy="0.166667" iyz="0" izz="0.166667"/>
    </inertial>
    <collision name="model__collision">
      <origin rpy="0  0  0" xyz="-3.00000000e-05  -1.92800000e-02  -9.19500000e-02"/>
      <geometry>
        <mesh filename="/home/pratik/review2/src/demo_car/meshes/base_full.stl" scale="1 1 1"/>
      </geometry>
    </collision>
    <visual name="model__visual">
      <origin rpy="0  0  0" xyz="-3.00000000e-05  -1.92800000e-02  -9.19500000e-02"/>
      <geometry>
        <mesh filename="/home/pratik/review2/src/demo_car/meshes/base_full.stl" scale="1 1 1"/>
      </geometry>
    </visual>
  </link>
  <link name="model__link_1">
    <inertial>
      <mass value="1"/>
      <origin rpy="0  0  0" xyz="0  0  0"/>
      <inertia ixx="0.166667" ixy="0" ixz="0" iyy="0.166667" iyz="0" izz="0.166667"/>
    </inertial>
    <collision name="model__collision">
      <origin rpy="0  0  0" xyz="0    -0.115  0"/>
      <geometry>
        <mesh filename="/home/pratik/review2/src/demo_car/meshes/wheel_fr.stl" scale="1 1 1"/>
      </geometry>
    </collision>
    <visual name="model__visual">
      <origin rpy="0  0  0" xyz="0    -0.115  0"/>
      <geometry>
        <mesh filename="/home/pratik/review2/src/demo_car/meshes/wheel_fr.stl" scale="1 1 1"/>
      </geometry>
    </visual>
  </link>
  <link name="model__link_2">
    <inertial>
      <mass value="1"/>
      <origin rpy="0  0  0" xyz="0  0  0"/>
      <inertia ixx="0.166667" ixy="0" ixz="0" iyy="0.166667" iyz="0" izz="0.166667"/>
    </inertial>
    <collision name="model__collision">
      <origin rpy="0  0  0" xyz="0    -0.115  0"/>
      <geometry>
        <mesh filename="/home/pratik/review2/src/demo_car/meshes/wheel_fr.stl" scale="1 1 1"/>
      </geometry>
    </collision>
    <visual name="model__visual">
      <origin rpy="0  0  0" xyz="0    -0.115  0"/>
      <geometry>
        <mesh filename="/home/pratik/review2/src/demo_car/meshes/wheel_fr.stl" scale="1 1 1"/>
      </geometry>
    </visual>
  </link>
  <link name="model__link_3">
    <inertial>
      <mass value="1"/>
      <origin rpy="0  0  0" xyz="0  0  0"/>
      <inertia ixx="0.166667" ixy="0" ixz="0" iyy="0.166667" iyz="0" izz="0.166667"/>
    </inertial>
    <collision name="model__collision">
      <origin rpy="0  0  0" xyz="0    -0.115  0"/>
      <geometry>
        <mesh filename="/home/pratik/review2/src/demo_car/meshes/wheel_fr.stl" scale="1 1 1"/>
      </geometry>
    </collision>
    <visual name="model__visual">
      <origin rpy="0  0  0" xyz="0    -0.115  0"/>
      <geometry>
        <mesh filename="/home/pratik/review2/src/demo_car/meshes/wheel_fr.stl" scale="1 1 1"/>
      </geometry>
    </visual>
  </link>
  <link name="model__link_4">
    <inertial>
      <mass value="1"/>
      <origin rpy="0  0  0" xyz="0  0  0"/>
      <inertia ixx="0.166667" ixy="0" ixz="0" iyy="0.166667" iyz="0" izz="0.166667"/>
    </inertial>
    <collision name="model__collision">
      <origin rpy="0  0  0" xyz="0    -0.115  0"/>
      <geometry>
        <mesh filename="/home/pratik/review2/src/demo_car/meshes/wheel_fr.stl" scale="1 1 1"/>
      </geometry>
    </collision>
    <visual name="model__visual">
      <origin rpy="0  0  0" xyz="0    -0.115  0"/>
      <geometry>
        <mesh filename="/home/pratik/review2/src/demo_car/meshes/wheel_fr.stl" scale="1 1 1"/>
      </geometry>
    </visual>
  </link>




<gazebo>
  <plugin name="skid_steer_drive_controller" filename="libgazebo_ros_skid_steer_drive.so">
    <updateRate>100.0</updateRate>
    <robotNamespace>/</robotNamespace>
    <leftFrontJoint>model__link_0_JOINT_1</leftFrontJoint>
    <rightFrontJoint>model__link_0_JOINT_0</rightFrontJoint>
    <leftRearJoint>model__link_0_JOINT_3</leftRearJoint>
    <rightRearJoint>model__link_0_JOINT_2</rightRearJoint>
    <wheelSeparation>0.212</wheelSeparation>
    <wheelDiameter>0.01</wheelDiameter>
    <robotBaseFrame>model__link_0</robotBaseFrame>
    <torque>0.5</torque>
    <topicName>cmd_vel</topicName>
    <broadcastTF>false</broadcastTF>
  </plugin>
</gazebo>
<gazebo>
 <plugin name="teleop_twist_joy" filename="libTeleopTwistJoyPlugin.so">
      <input_topic>/joy</input_topic>
      <output_topic>/cmd_vel</output_topic>
      <enable_button>10</enable_button>
      <axis_linear>3</axis_linear>
      <scale_linear>1.0</scale_linear>
      <axis_angular>0</axis_angular>
      <scale_angular>1.0</scale_angular>
    </plugin>
</gazebo>
</robot>
